2025-08-06 13:45:16,428 [ERROR] fastapi [utils.py:114]: Form data requires "python-multipart" to be installed. 
You can install "python-multipart" with: 

pip install python-multipart

2025-08-06 13:45:43,056 [ERROR] uvicorn.error [on.py:121]: Traceback (most recent call last):
  File "/usr/local/lib/python3.11/dist-packages/starlette/routing.py", line 694, in lifespan
    async with self.lifespan_context(app) as maybe_state:
  File "/usr/lib/python3.11/contextlib.py", line 204, in __aenter__
    return await anext(self.gen)
           ^^^^^^^^^^^^^^^^^^^^^
  File "/usr/local/lib/python3.11/dist-packages/fastapi/routing.py", line 134, in merged_lifespan
    async with original_context(app) as maybe_original_state:
  File "/usr/lib/python3.11/contextlib.py", line 204, in __aenter__
    return await anext(self.gen)
           ^^^^^^^^^^^^^^^^^^^^^
  File "/usr/local/lib/python3.11/dist-packages/fastapi/routing.py", line 134, in merged_lifespan
    async with original_context(app) as maybe_original_state:
  File "/usr/lib/python3.11/contextlib.py", line 204, in __aenter__
    return await anext(self.gen)
           ^^^^^^^^^^^^^^^^^^^^^
  File "/usr/local/lib/python3.11/dist-packages/fastapi/routing.py", line 134, in merged_lifespan
    async with original_context(app) as maybe_original_state:
  File "/usr/lib/python3.11/contextlib.py", line 204, in __aenter__
    return await anext(self.gen)
           ^^^^^^^^^^^^^^^^^^^^^
  File "/usr/local/lib/python3.11/dist-packages/fastapi/routing.py", line 134, in merged_lifespan
    async with original_context(app) as maybe_original_state:
  File "/usr/lib/python3.11/contextlib.py", line 204, in __aenter__
    return await anext(self.gen)
           ^^^^^^^^^^^^^^^^^^^^^
  File "/usr/local/lib/python3.11/dist-packages/fastapi/routing.py", line 134, in merged_lifespan
    async with original_context(app) as maybe_original_state:
  File "/usr/lib/python3.11/contextlib.py", line 204, in __aenter__
    return await anext(self.gen)
           ^^^^^^^^^^^^^^^^^^^^^
  File "/usr/local/lib/python3.11/dist-packages/fastapi/routing.py", line 134, in merged_lifespan
    async with original_context(app) as maybe_original_state:
  File "/usr/lib/python3.11/contextlib.py", line 204, in __aenter__
    return await anext(self.gen)
           ^^^^^^^^^^^^^^^^^^^^^
  File "/home/ubuntu/crypto-0DTE-system/backend/app/main.py", line 46, in lifespan
    async with engine.begin() as conn:
  File "/usr/lib/python3.11/contextlib.py", line 204, in __aenter__
    return await anext(self.gen)
           ^^^^^^^^^^^^^^^^^^^^^
  File "/usr/local/lib/python3.11/dist-packages/sqlalchemy/ext/asyncio/engine.py", line 1066, in begin
    async with conn:
  File "/usr/local/lib/python3.11/dist-packages/sqlalchemy/ext/asyncio/base.py", line 121, in __aenter__
    return await self.start(is_ctxmanager=True)
           ^^^^^^^^^^^^^^^^^^^^^^^^^^^^^^^^^^^^
  File "/usr/local/lib/python3.11/dist-packages/sqlalchemy/ext/asyncio/engine.py", line 274, in start
    await greenlet_spawn(self.sync_engine.connect)
  File "/usr/local/lib/python3.11/dist-packages/sqlalchemy/util/_concurrency_py3k.py", line 201, in greenlet_spawn
    result = context.throw(*sys.exc_info())
             ^^^^^^^^^^^^^^^^^^^^^^^^^^^^^^
  File "/usr/local/lib/python3.11/dist-packages/sqlalchemy/engine/base.py", line 3271, in connect
    return self._connection_cls(self)
           ^^^^^^^^^^^^^^^^^^^^^^^^^^
  File "/usr/local/lib/python3.11/dist-packages/sqlalchemy/engine/base.py", line 143, in __init__
    self._dbapi_connection = engine.raw_connection()
                             ^^^^^^^^^^^^^^^^^^^^^^^
  File "/usr/local/lib/python3.11/dist-packages/sqlalchemy/engine/base.py", line 3295, in raw_connection
    return self.pool.connect()
           ^^^^^^^^^^^^^^^^^^^
  File "/usr/local/lib/python3.11/dist-packages/sqlalchemy/pool/base.py", line 447, in connect
    return _ConnectionFairy._checkout(self)
           ^^^^^^^^^^^^^^^^^^^^^^^^^^^^^^^^
  File "/usr/local/lib/python3.11/dist-packages/sqlalchemy/pool/base.py", line 1264, in _checkout
    fairy = _ConnectionRecord.checkout(pool)
            ^^^^^^^^^^^^^^^^^^^^^^^^^^^^^^^^
  File "/usr/local/lib/python3.11/dist-packages/sqlalchemy/pool/base.py", line 711, in checkout
    rec = pool._do_get()
          ^^^^^^^^^^^^^^
  File "/usr/local/lib/python3.11/dist-packages/sqlalchemy/pool/impl.py", line 177, in _do_get
    with util.safe_reraise():
  File "/usr/local/lib/python3.11/dist-packages/sqlalchemy/util/langhelpers.py", line 224, in __exit__
    raise exc_value.with_traceback(exc_tb)
  File "/usr/local/lib/python3.11/dist-packages/sqlalchemy/pool/impl.py", line 175, in _do_get
    return self._create_connection()
           ^^^^^^^^^^^^^^^^^^^^^^^^^
  File "/usr/local/lib/python3.11/dist-packages/sqlalchemy/pool/base.py", line 388, in _create_connection
    return _ConnectionRecord(self)
           ^^^^^^^^^^^^^^^^^^^^^^^
  File "/usr/local/lib/python3.11/dist-packages/sqlalchemy/pool/base.py", line 673, in __init__
    self.__connect()
  File "/usr/local/lib/python3.11/dist-packages/sqlalchemy/pool/base.py", line 899, in __connect
    with util.safe_reraise():
  File "/usr/local/lib/python3.11/dist-packages/sqlalchemy/util/langhelpers.py", line 224, in __exit__
    raise exc_value.with_traceback(exc_tb)
  File "/usr/local/lib/python3.11/dist-packages/sqlalchemy/pool/base.py", line 895, in __connect
    self.dbapi_connection = connection = pool._invoke_creator(self)
                                         ^^^^^^^^^^^^^^^^^^^^^^^^^^
  File "/usr/local/lib/python3.11/dist-packages/sqlalchemy/engine/create.py", line 646, in connect
    return dialect.connect(*cargs, **cparams)
           ^^^^^^^^^^^^^^^^^^^^^^^^^^^^^^^^^^
  File "/usr/local/lib/python3.11/dist-packages/sqlalchemy/engine/default.py", line 626, in connect
    return self.loaded_dbapi.connect(*cargs, **cparams)  # type: ignore[no-any-return]  # NOQA: E501
           ^^^^^^^^^^^^^^^^^^^^^^^^^^^^^^^^^^^^^^^^^^^^
  File "/usr/local/lib/python3.11/dist-packages/sqlalchemy/dialects/postgresql/asyncpg.py", line 964, in connect
    await_only(creator_fn(*arg, **kw)),
    ^^^^^^^^^^^^^^^^^^^^^^^^^^^^^^^^^^
  File "/usr/local/lib/python3.11/dist-packages/sqlalchemy/util/_concurrency_py3k.py", line 132, in await_only
    return current.parent.switch(awaitable)  # type: ignore[no-any-return,attr-defined] # noqa: E501
           ^^^^^^^^^^^^^^^^^^^^^^^^^^^^^^^^
  File "/usr/local/lib/python3.11/dist-packages/sqlalchemy/util/_concurrency_py3k.py", line 196, in greenlet_spawn
    value = await result
            ^^^^^^^^^^^^
  File "/usr/local/lib/python3.11/dist-packages/asyncpg/connection.py", line 2421, in connect
    return await connect_utils._connect(
           ^^^^^^^^^^^^^^^^^^^^^^^^^^^^^
  File "/usr/local/lib/python3.11/dist-packages/asyncpg/connect_utils.py", line 1075, in _connect
    raise last_error or exceptions.TargetServerAttributeNotMatched(
  File "/usr/local/lib/python3.11/dist-packages/asyncpg/connect_utils.py", line 1049, in _connect
    conn = await _connect_addr(
           ^^^^^^^^^^^^^^^^^^^^
  File "/usr/local/lib/python3.11/dist-packages/asyncpg/connect_utils.py", line 886, in _connect_addr
    return await __connect_addr(params, True, *args)
           ^^^^^^^^^^^^^^^^^^^^^^^^^^^^^^^^^^^^^^^^^
  File "/usr/local/lib/python3.11/dist-packages/asyncpg/connect_utils.py", line 931, in __connect_addr
    tr, pr = await connector
             ^^^^^^^^^^^^^^^
  File "/usr/local/lib/python3.11/dist-packages/asyncpg/connect_utils.py", line 802, in _create_ssl_connection
    tr, pr = await loop.create_connection(
             ^^^^^^^^^^^^^^^^^^^^^^^^^^^^^
  File "uvloop/loop.pyx", line 2043, in create_connection
  File "uvloop/loop.pyx", line 2020, in uvloop.loop.Loop.create_connection
ConnectionRefusedError: [Errno 111] Connection refused

2025-08-06 13:45:43,056 [ERROR] uvicorn.error [on.py:59]: Application startup failed. Exiting.
2025-08-06 14:16:41,047 [ERROR] uvicorn.error [on.py:121]: Traceback (most recent call last):
  File "/usr/local/lib/python3.11/dist-packages/starlette/routing.py", line 694, in lifespan
    async with self.lifespan_context(app) as maybe_state:
  File "/usr/lib/python3.11/contextlib.py", line 204, in __aenter__
    return await anext(self.gen)
           ^^^^^^^^^^^^^^^^^^^^^
  File "/usr/local/lib/python3.11/dist-packages/fastapi/routing.py", line 134, in merged_lifespan
    async with original_context(app) as maybe_original_state:
  File "/usr/lib/python3.11/contextlib.py", line 204, in __aenter__
    return await anext(self.gen)
           ^^^^^^^^^^^^^^^^^^^^^
  File "/usr/local/lib/python3.11/dist-packages/fastapi/routing.py", line 134, in merged_lifespan
    async with original_context(app) as maybe_original_state:
  File "/usr/lib/python3.11/contextlib.py", line 204, in __aenter__
    return await anext(self.gen)
           ^^^^^^^^^^^^^^^^^^^^^
  File "/usr/local/lib/python3.11/dist-packages/fastapi/routing.py", line 134, in merged_lifespan
    async with original_context(app) as maybe_original_state:
  File "/usr/lib/python3.11/contextlib.py", line 204, in __aenter__
    return await anext(self.gen)
           ^^^^^^^^^^^^^^^^^^^^^
  File "/usr/local/lib/python3.11/dist-packages/fastapi/routing.py", line 134, in merged_lifespan
    async with original_context(app) as maybe_original_state:
  File "/usr/lib/python3.11/contextlib.py", line 204, in __aenter__
    return await anext(self.gen)
           ^^^^^^^^^^^^^^^^^^^^^
  File "/usr/local/lib/python3.11/dist-packages/fastapi/routing.py", line 134, in merged_lifespan
    async with original_context(app) as maybe_original_state:
  File "/usr/lib/python3.11/contextlib.py", line 204, in __aenter__
    return await anext(self.gen)
           ^^^^^^^^^^^^^^^^^^^^^
  File "/usr/local/lib/python3.11/dist-packages/fastapi/routing.py", line 134, in merged_lifespan
    async with original_context(app) as maybe_original_state:
  File "/usr/lib/python3.11/contextlib.py", line 204, in __aenter__
    return await anext(self.gen)
           ^^^^^^^^^^^^^^^^^^^^^
  File "/home/ubuntu/crypto-0DTE-system/backend/app/main.py", line 46, in lifespan
    async with engine.begin() as conn:
  File "/usr/lib/python3.11/contextlib.py", line 204, in __aenter__
    return await anext(self.gen)
           ^^^^^^^^^^^^^^^^^^^^^
  File "/usr/local/lib/python3.11/dist-packages/sqlalchemy/ext/asyncio/engine.py", line 1066, in begin
    async with conn:
  File "/usr/local/lib/python3.11/dist-packages/sqlalchemy/ext/asyncio/base.py", line 121, in __aenter__
    return await self.start(is_ctxmanager=True)
           ^^^^^^^^^^^^^^^^^^^^^^^^^^^^^^^^^^^^
  File "/usr/local/lib/python3.11/dist-packages/sqlalchemy/ext/asyncio/engine.py", line 274, in start
    await greenlet_spawn(self.sync_engine.connect)
  File "/usr/local/lib/python3.11/dist-packages/sqlalchemy/util/_concurrency_py3k.py", line 201, in greenlet_spawn
    result = context.throw(*sys.exc_info())
             ^^^^^^^^^^^^^^^^^^^^^^^^^^^^^^
  File "/usr/local/lib/python3.11/dist-packages/sqlalchemy/engine/base.py", line 3271, in connect
    return self._connection_cls(self)
           ^^^^^^^^^^^^^^^^^^^^^^^^^^
  File "/usr/local/lib/python3.11/dist-packages/sqlalchemy/engine/base.py", line 143, in __init__
    self._dbapi_connection = engine.raw_connection()
                             ^^^^^^^^^^^^^^^^^^^^^^^
  File "/usr/local/lib/python3.11/dist-packages/sqlalchemy/engine/base.py", line 3295, in raw_connection
    return self.pool.connect()
           ^^^^^^^^^^^^^^^^^^^
  File "/usr/local/lib/python3.11/dist-packages/sqlalchemy/pool/base.py", line 447, in connect
    return _ConnectionFairy._checkout(self)
           ^^^^^^^^^^^^^^^^^^^^^^^^^^^^^^^^
  File "/usr/local/lib/python3.11/dist-packages/sqlalchemy/pool/base.py", line 1264, in _checkout
    fairy = _ConnectionRecord.checkout(pool)
            ^^^^^^^^^^^^^^^^^^^^^^^^^^^^^^^^
  File "/usr/local/lib/python3.11/dist-packages/sqlalchemy/pool/base.py", line 711, in checkout
    rec = pool._do_get()
          ^^^^^^^^^^^^^^
  File "/usr/local/lib/python3.11/dist-packages/sqlalchemy/pool/impl.py", line 177, in _do_get
    with util.safe_reraise():
  File "/usr/local/lib/python3.11/dist-packages/sqlalchemy/util/langhelpers.py", line 224, in __exit__
    raise exc_value.with_traceback(exc_tb)
  File "/usr/local/lib/python3.11/dist-packages/sqlalchemy/pool/impl.py", line 175, in _do_get
    return self._create_connection()
           ^^^^^^^^^^^^^^^^^^^^^^^^^
  File "/usr/local/lib/python3.11/dist-packages/sqlalchemy/pool/base.py", line 388, in _create_connection
    return _ConnectionRecord(self)
           ^^^^^^^^^^^^^^^^^^^^^^^
  File "/usr/local/lib/python3.11/dist-packages/sqlalchemy/pool/base.py", line 673, in __init__
    self.__connect()
  File "/usr/local/lib/python3.11/dist-packages/sqlalchemy/pool/base.py", line 899, in __connect
    with util.safe_reraise():
  File "/usr/local/lib/python3.11/dist-packages/sqlalchemy/util/langhelpers.py", line 224, in __exit__
    raise exc_value.with_traceback(exc_tb)
  File "/usr/local/lib/python3.11/dist-packages/sqlalchemy/pool/base.py", line 895, in __connect
    self.dbapi_connection = connection = pool._invoke_creator(self)
                                         ^^^^^^^^^^^^^^^^^^^^^^^^^^
  File "/usr/local/lib/python3.11/dist-packages/sqlalchemy/engine/create.py", line 646, in connect
    return dialect.connect(*cargs, **cparams)
           ^^^^^^^^^^^^^^^^^^^^^^^^^^^^^^^^^^
  File "/usr/local/lib/python3.11/dist-packages/sqlalchemy/engine/default.py", line 626, in connect
    return self.loaded_dbapi.connect(*cargs, **cparams)  # type: ignore[no-any-return]  # NOQA: E501
           ^^^^^^^^^^^^^^^^^^^^^^^^^^^^^^^^^^^^^^^^^^^^
  File "/usr/local/lib/python3.11/dist-packages/sqlalchemy/dialects/postgresql/asyncpg.py", line 964, in connect
    await_only(creator_fn(*arg, **kw)),
    ^^^^^^^^^^^^^^^^^^^^^^^^^^^^^^^^^^
  File "/usr/local/lib/python3.11/dist-packages/sqlalchemy/util/_concurrency_py3k.py", line 132, in await_only
    return current.parent.switch(awaitable)  # type: ignore[no-any-return,attr-defined] # noqa: E501
           ^^^^^^^^^^^^^^^^^^^^^^^^^^^^^^^^
  File "/usr/local/lib/python3.11/dist-packages/sqlalchemy/util/_concurrency_py3k.py", line 196, in greenlet_spawn
    value = await result
            ^^^^^^^^^^^^
  File "/usr/local/lib/python3.11/dist-packages/asyncpg/connection.py", line 2421, in connect
    return await connect_utils._connect(
           ^^^^^^^^^^^^^^^^^^^^^^^^^^^^^
  File "/usr/local/lib/python3.11/dist-packages/asyncpg/connect_utils.py", line 1075, in _connect
    raise last_error or exceptions.TargetServerAttributeNotMatched(
  File "/usr/local/lib/python3.11/dist-packages/asyncpg/connect_utils.py", line 1049, in _connect
    conn = await _connect_addr(
           ^^^^^^^^^^^^^^^^^^^^
  File "/usr/local/lib/python3.11/dist-packages/asyncpg/connect_utils.py", line 886, in _connect_addr
    return await __connect_addr(params, True, *args)
           ^^^^^^^^^^^^^^^^^^^^^^^^^^^^^^^^^^^^^^^^^
  File "/usr/local/lib/python3.11/dist-packages/asyncpg/connect_utils.py", line 931, in __connect_addr
    tr, pr = await connector
             ^^^^^^^^^^^^^^^
  File "/usr/local/lib/python3.11/dist-packages/asyncpg/connect_utils.py", line 802, in _create_ssl_connection
    tr, pr = await loop.create_connection(
             ^^^^^^^^^^^^^^^^^^^^^^^^^^^^^
  File "uvloop/loop.pyx", line 2043, in create_connection
  File "uvloop/loop.pyx", line 2020, in uvloop.loop.Loop.create_connection
ConnectionRefusedError: [Errno 111] Connection refused

2025-08-06 14:16:41,047 [ERROR] uvicorn.error [on.py:59]: Application startup failed. Exiting.
2025-08-06 14:30:55,581 [ERROR] uvicorn.error [on.py:121]: Traceback (most recent call last):
  File "/usr/local/lib/python3.11/dist-packages/starlette/routing.py", line 694, in lifespan
    async with self.lifespan_context(app) as maybe_state:
  File "/usr/lib/python3.11/contextlib.py", line 204, in __aenter__
    return await anext(self.gen)
           ^^^^^^^^^^^^^^^^^^^^^
  File "/usr/local/lib/python3.11/dist-packages/fastapi/routing.py", line 134, in merged_lifespan
    async with original_context(app) as maybe_original_state:
  File "/usr/lib/python3.11/contextlib.py", line 204, in __aenter__
    return await anext(self.gen)
           ^^^^^^^^^^^^^^^^^^^^^
  File "/usr/local/lib/python3.11/dist-packages/fastapi/routing.py", line 134, in merged_lifespan
    async with original_context(app) as maybe_original_state:
  File "/usr/lib/python3.11/contextlib.py", line 204, in __aenter__
    return await anext(self.gen)
           ^^^^^^^^^^^^^^^^^^^^^
  File "/usr/local/lib/python3.11/dist-packages/fastapi/routing.py", line 134, in merged_lifespan
    async with original_context(app) as maybe_original_state:
  File "/usr/lib/python3.11/contextlib.py", line 204, in __aenter__
    return await anext(self.gen)
           ^^^^^^^^^^^^^^^^^^^^^
  File "/usr/local/lib/python3.11/dist-packages/fastapi/routing.py", line 134, in merged_lifespan
    async with original_context(app) as maybe_original_state:
  File "/usr/lib/python3.11/contextlib.py", line 204, in __aenter__
    return await anext(self.gen)
           ^^^^^^^^^^^^^^^^^^^^^
  File "/usr/local/lib/python3.11/dist-packages/fastapi/routing.py", line 134, in merged_lifespan
    async with original_context(app) as maybe_original_state:
  File "/usr/lib/python3.11/contextlib.py", line 204, in __aenter__
    return await anext(self.gen)
           ^^^^^^^^^^^^^^^^^^^^^
  File "/usr/local/lib/python3.11/dist-packages/fastapi/routing.py", line 134, in merged_lifespan
    async with original_context(app) as maybe_original_state:
  File "/usr/lib/python3.11/contextlib.py", line 204, in __aenter__
    return await anext(self.gen)
           ^^^^^^^^^^^^^^^^^^^^^
  File "/home/ubuntu/crypto-0DTE-system/backend/app/main.py", line 46, in lifespan
    async with engine.begin() as conn:
  File "/usr/lib/python3.11/contextlib.py", line 204, in __aenter__
    return await anext(self.gen)
           ^^^^^^^^^^^^^^^^^^^^^
  File "/usr/local/lib/python3.11/dist-packages/sqlalchemy/ext/asyncio/engine.py", line 1066, in begin
    async with conn:
  File "/usr/local/lib/python3.11/dist-packages/sqlalchemy/ext/asyncio/base.py", line 121, in __aenter__
    return await self.start(is_ctxmanager=True)
           ^^^^^^^^^^^^^^^^^^^^^^^^^^^^^^^^^^^^
  File "/usr/local/lib/python3.11/dist-packages/sqlalchemy/ext/asyncio/engine.py", line 274, in start
    await greenlet_spawn(self.sync_engine.connect)
  File "/usr/local/lib/python3.11/dist-packages/sqlalchemy/util/_concurrency_py3k.py", line 201, in greenlet_spawn
    result = context.throw(*sys.exc_info())
             ^^^^^^^^^^^^^^^^^^^^^^^^^^^^^^
  File "/usr/local/lib/python3.11/dist-packages/sqlalchemy/engine/base.py", line 3271, in connect
    return self._connection_cls(self)
           ^^^^^^^^^^^^^^^^^^^^^^^^^^
  File "/usr/local/lib/python3.11/dist-packages/sqlalchemy/engine/base.py", line 143, in __init__
    self._dbapi_connection = engine.raw_connection()
                             ^^^^^^^^^^^^^^^^^^^^^^^
  File "/usr/local/lib/python3.11/dist-packages/sqlalchemy/engine/base.py", line 3295, in raw_connection
    return self.pool.connect()
           ^^^^^^^^^^^^^^^^^^^
  File "/usr/local/lib/python3.11/dist-packages/sqlalchemy/pool/base.py", line 447, in connect
    return _ConnectionFairy._checkout(self)
           ^^^^^^^^^^^^^^^^^^^^^^^^^^^^^^^^
  File "/usr/local/lib/python3.11/dist-packages/sqlalchemy/pool/base.py", line 1264, in _checkout
    fairy = _ConnectionRecord.checkout(pool)
            ^^^^^^^^^^^^^^^^^^^^^^^^^^^^^^^^
  File "/usr/local/lib/python3.11/dist-packages/sqlalchemy/pool/base.py", line 711, in checkout
    rec = pool._do_get()
          ^^^^^^^^^^^^^^
  File "/usr/local/lib/python3.11/dist-packages/sqlalchemy/pool/impl.py", line 177, in _do_get
    with util.safe_reraise():
  File "/usr/local/lib/python3.11/dist-packages/sqlalchemy/util/langhelpers.py", line 224, in __exit__
    raise exc_value.with_traceback(exc_tb)
  File "/usr/local/lib/python3.11/dist-packages/sqlalchemy/pool/impl.py", line 175, in _do_get
    return self._create_connection()
           ^^^^^^^^^^^^^^^^^^^^^^^^^
  File "/usr/local/lib/python3.11/dist-packages/sqlalchemy/pool/base.py", line 388, in _create_connection
    return _ConnectionRecord(self)
           ^^^^^^^^^^^^^^^^^^^^^^^
  File "/usr/local/lib/python3.11/dist-packages/sqlalchemy/pool/base.py", line 673, in __init__
    self.__connect()
  File "/usr/local/lib/python3.11/dist-packages/sqlalchemy/pool/base.py", line 899, in __connect
    with util.safe_reraise():
  File "/usr/local/lib/python3.11/dist-packages/sqlalchemy/util/langhelpers.py", line 224, in __exit__
    raise exc_value.with_traceback(exc_tb)
  File "/usr/local/lib/python3.11/dist-packages/sqlalchemy/pool/base.py", line 895, in __connect
    self.dbapi_connection = connection = pool._invoke_creator(self)
                                         ^^^^^^^^^^^^^^^^^^^^^^^^^^
  File "/usr/local/lib/python3.11/dist-packages/sqlalchemy/engine/create.py", line 646, in connect
    return dialect.connect(*cargs, **cparams)
           ^^^^^^^^^^^^^^^^^^^^^^^^^^^^^^^^^^
  File "/usr/local/lib/python3.11/dist-packages/sqlalchemy/engine/default.py", line 626, in connect
    return self.loaded_dbapi.connect(*cargs, **cparams)  # type: ignore[no-any-return]  # NOQA: E501
           ^^^^^^^^^^^^^^^^^^^^^^^^^^^^^^^^^^^^^^^^^^^^
  File "/usr/local/lib/python3.11/dist-packages/sqlalchemy/dialects/postgresql/asyncpg.py", line 964, in connect
    await_only(creator_fn(*arg, **kw)),
    ^^^^^^^^^^^^^^^^^^^^^^^^^^^^^^^^^^
  File "/usr/local/lib/python3.11/dist-packages/sqlalchemy/util/_concurrency_py3k.py", line 132, in await_only
    return current.parent.switch(awaitable)  # type: ignore[no-any-return,attr-defined] # noqa: E501
           ^^^^^^^^^^^^^^^^^^^^^^^^^^^^^^^^
  File "/usr/local/lib/python3.11/dist-packages/sqlalchemy/util/_concurrency_py3k.py", line 196, in greenlet_spawn
    value = await result
            ^^^^^^^^^^^^
  File "/usr/local/lib/python3.11/dist-packages/asyncpg/connection.py", line 2421, in connect
    return await connect_utils._connect(
           ^^^^^^^^^^^^^^^^^^^^^^^^^^^^^
  File "/usr/local/lib/python3.11/dist-packages/asyncpg/connect_utils.py", line 1075, in _connect
    raise last_error or exceptions.TargetServerAttributeNotMatched(
  File "/usr/local/lib/python3.11/dist-packages/asyncpg/connect_utils.py", line 1049, in _connect
    conn = await _connect_addr(
           ^^^^^^^^^^^^^^^^^^^^
  File "/usr/local/lib/python3.11/dist-packages/asyncpg/connect_utils.py", line 886, in _connect_addr
    return await __connect_addr(params, True, *args)
           ^^^^^^^^^^^^^^^^^^^^^^^^^^^^^^^^^^^^^^^^^
  File "/usr/local/lib/python3.11/dist-packages/asyncpg/connect_utils.py", line 931, in __connect_addr
    tr, pr = await connector
             ^^^^^^^^^^^^^^^
  File "/usr/local/lib/python3.11/dist-packages/asyncpg/connect_utils.py", line 802, in _create_ssl_connection
    tr, pr = await loop.create_connection(
             ^^^^^^^^^^^^^^^^^^^^^^^^^^^^^
  File "uvloop/loop.pyx", line 2043, in create_connection
  File "uvloop/loop.pyx", line 2020, in uvloop.loop.Loop.create_connection
ConnectionRefusedError: [Errno 111] Connection refused

2025-08-06 14:30:55,581 [ERROR] uvicorn.error [on.py:59]: Application startup failed. Exiting.
2025-08-08 10:31:43,126 [ERROR] uvicorn.error [on.py:121]: Traceback (most recent call last):
  File "/usr/local/lib/python3.11/dist-packages/starlette/routing.py", line 694, in lifespan
    async with self.lifespan_context(app) as maybe_state:
  File "/usr/lib/python3.11/contextlib.py", line 204, in __aenter__
    return await anext(self.gen)
           ^^^^^^^^^^^^^^^^^^^^^
  File "/usr/local/lib/python3.11/dist-packages/fastapi/routing.py", line 134, in merged_lifespan
    async with original_context(app) as maybe_original_state:
  File "/usr/lib/python3.11/contextlib.py", line 204, in __aenter__
    return await anext(self.gen)
           ^^^^^^^^^^^^^^^^^^^^^
  File "/usr/local/lib/python3.11/dist-packages/fastapi/routing.py", line 134, in merged_lifespan
    async with original_context(app) as maybe_original_state:
  File "/usr/lib/python3.11/contextlib.py", line 204, in __aenter__
    return await anext(self.gen)
           ^^^^^^^^^^^^^^^^^^^^^
  File "/usr/local/lib/python3.11/dist-packages/fastapi/routing.py", line 134, in merged_lifespan
    async with original_context(app) as maybe_original_state:
  File "/usr/lib/python3.11/contextlib.py", line 204, in __aenter__
    return await anext(self.gen)
           ^^^^^^^^^^^^^^^^^^^^^
  File "/usr/local/lib/python3.11/dist-packages/fastapi/routing.py", line 134, in merged_lifespan
    async with original_context(app) as maybe_original_state:
  File "/usr/lib/python3.11/contextlib.py", line 204, in __aenter__
    return await anext(self.gen)
           ^^^^^^^^^^^^^^^^^^^^^
  File "/usr/local/lib/python3.11/dist-packages/fastapi/routing.py", line 134, in merged_lifespan
    async with original_context(app) as maybe_original_state:
  File "/usr/lib/python3.11/contextlib.py", line 204, in __aenter__
    return await anext(self.gen)
           ^^^^^^^^^^^^^^^^^^^^^
  File "/usr/local/lib/python3.11/dist-packages/fastapi/routing.py", line 134, in merged_lifespan
    async with original_context(app) as maybe_original_state:
  File "/usr/lib/python3.11/contextlib.py", line 204, in __aenter__
    return await anext(self.gen)
           ^^^^^^^^^^^^^^^^^^^^^
  File "/home/ubuntu/crypto-0DTE-system/backend/app/main.py", line 61, in lifespan
    async with engine.begin() as conn:
  File "/usr/lib/python3.11/contextlib.py", line 204, in __aenter__
    return await anext(self.gen)
           ^^^^^^^^^^^^^^^^^^^^^
  File "/usr/local/lib/python3.11/dist-packages/sqlalchemy/ext/asyncio/engine.py", line 1066, in begin
    async with conn:
  File "/usr/local/lib/python3.11/dist-packages/sqlalchemy/ext/asyncio/base.py", line 121, in __aenter__
    return await self.start(is_ctxmanager=True)
           ^^^^^^^^^^^^^^^^^^^^^^^^^^^^^^^^^^^^
  File "/usr/local/lib/python3.11/dist-packages/sqlalchemy/ext/asyncio/engine.py", line 274, in start
    await greenlet_spawn(self.sync_engine.connect)
  File "/usr/local/lib/python3.11/dist-packages/sqlalchemy/util/_concurrency_py3k.py", line 201, in greenlet_spawn
    result = context.throw(*sys.exc_info())
             ^^^^^^^^^^^^^^^^^^^^^^^^^^^^^^
  File "/usr/local/lib/python3.11/dist-packages/sqlalchemy/engine/base.py", line 3271, in connect
    return self._connection_cls(self)
           ^^^^^^^^^^^^^^^^^^^^^^^^^^
  File "/usr/local/lib/python3.11/dist-packages/sqlalchemy/engine/base.py", line 143, in __init__
    self._dbapi_connection = engine.raw_connection()
                             ^^^^^^^^^^^^^^^^^^^^^^^
  File "/usr/local/lib/python3.11/dist-packages/sqlalchemy/engine/base.py", line 3295, in raw_connection
    return self.pool.connect()
           ^^^^^^^^^^^^^^^^^^^
  File "/usr/local/lib/python3.11/dist-packages/sqlalchemy/pool/base.py", line 447, in connect
    return _ConnectionFairy._checkout(self)
           ^^^^^^^^^^^^^^^^^^^^^^^^^^^^^^^^
  File "/usr/local/lib/python3.11/dist-packages/sqlalchemy/pool/base.py", line 1264, in _checkout
    fairy = _ConnectionRecord.checkout(pool)
            ^^^^^^^^^^^^^^^^^^^^^^^^^^^^^^^^
  File "/usr/local/lib/python3.11/dist-packages/sqlalchemy/pool/base.py", line 711, in checkout
    rec = pool._do_get()
          ^^^^^^^^^^^^^^
  File "/usr/local/lib/python3.11/dist-packages/sqlalchemy/pool/impl.py", line 177, in _do_get
    with util.safe_reraise():
  File "/usr/local/lib/python3.11/dist-packages/sqlalchemy/util/langhelpers.py", line 224, in __exit__
    raise exc_value.with_traceback(exc_tb)
  File "/usr/local/lib/python3.11/dist-packages/sqlalchemy/pool/impl.py", line 175, in _do_get
    return self._create_connection()
           ^^^^^^^^^^^^^^^^^^^^^^^^^
  File "/usr/local/lib/python3.11/dist-packages/sqlalchemy/pool/base.py", line 388, in _create_connection
    return _ConnectionRecord(self)
           ^^^^^^^^^^^^^^^^^^^^^^^
  File "/usr/local/lib/python3.11/dist-packages/sqlalchemy/pool/base.py", line 673, in __init__
    self.__connect()
  File "/usr/local/lib/python3.11/dist-packages/sqlalchemy/pool/base.py", line 899, in __connect
    with util.safe_reraise():
  File "/usr/local/lib/python3.11/dist-packages/sqlalchemy/util/langhelpers.py", line 224, in __exit__
    raise exc_value.with_traceback(exc_tb)
  File "/usr/local/lib/python3.11/dist-packages/sqlalchemy/pool/base.py", line 895, in __connect
    self.dbapi_connection = connection = pool._invoke_creator(self)
                                         ^^^^^^^^^^^^^^^^^^^^^^^^^^
  File "/usr/local/lib/python3.11/dist-packages/sqlalchemy/engine/create.py", line 646, in connect
    return dialect.connect(*cargs, **cparams)
           ^^^^^^^^^^^^^^^^^^^^^^^^^^^^^^^^^^
  File "/usr/local/lib/python3.11/dist-packages/sqlalchemy/engine/default.py", line 626, in connect
    return self.loaded_dbapi.connect(*cargs, **cparams)  # type: ignore[no-any-return]  # NOQA: E501
           ^^^^^^^^^^^^^^^^^^^^^^^^^^^^^^^^^^^^^^^^^^^^
  File "/usr/local/lib/python3.11/dist-packages/sqlalchemy/dialects/postgresql/asyncpg.py", line 964, in connect
    await_only(creator_fn(*arg, **kw)),
    ^^^^^^^^^^^^^^^^^^^^^^^^^^^^^^^^^^
  File "/usr/local/lib/python3.11/dist-packages/sqlalchemy/util/_concurrency_py3k.py", line 132, in await_only
    return current.parent.switch(awaitable)  # type: ignore[no-any-return,attr-defined] # noqa: E501
           ^^^^^^^^^^^^^^^^^^^^^^^^^^^^^^^^
  File "/usr/local/lib/python3.11/dist-packages/sqlalchemy/util/_concurrency_py3k.py", line 196, in greenlet_spawn
    value = await result
            ^^^^^^^^^^^^
  File "/usr/local/lib/python3.11/dist-packages/asyncpg/connection.py", line 2421, in connect
    return await connect_utils._connect(
           ^^^^^^^^^^^^^^^^^^^^^^^^^^^^^
  File "/usr/local/lib/python3.11/dist-packages/asyncpg/connect_utils.py", line 1075, in _connect
    raise last_error or exceptions.TargetServerAttributeNotMatched(
  File "/usr/local/lib/python3.11/dist-packages/asyncpg/connect_utils.py", line 1049, in _connect
    conn = await _connect_addr(
           ^^^^^^^^^^^^^^^^^^^^
  File "/usr/local/lib/python3.11/dist-packages/asyncpg/connect_utils.py", line 886, in _connect_addr
    return await __connect_addr(params, True, *args)
           ^^^^^^^^^^^^^^^^^^^^^^^^^^^^^^^^^^^^^^^^^
  File "/usr/local/lib/python3.11/dist-packages/asyncpg/connect_utils.py", line 931, in __connect_addr
    tr, pr = await connector
             ^^^^^^^^^^^^^^^
  File "/usr/local/lib/python3.11/dist-packages/asyncpg/connect_utils.py", line 802, in _create_ssl_connection
    tr, pr = await loop.create_connection(
             ^^^^^^^^^^^^^^^^^^^^^^^^^^^^^
  File "uvloop/loop.pyx", line 2043, in create_connection
  File "uvloop/loop.pyx", line 2020, in uvloop.loop.Loop.create_connection
ConnectionRefusedError: [Errno 111] Connection refused

2025-08-08 10:31:43,127 [ERROR] uvicorn.error [on.py:59]: Application startup failed. Exiting.
